<?xml version="1.0" ?>
<!-- =================================================================================== -->
<!-- |    This document was autogenerated by xacro from /home/akiyoshi_ochiai/Develop/Work/hsrb_simulator_ws/src/tmc_hsrb_common/tmc_hsrb_description/robots/hsrb.urdf.xacro | -->
<!-- |    EDITING THIS FILE BY HAND IS NOT RECOMMENDED                                 | -->
<!-- =================================================================================== -->
<robot name="hsrb" xmlns:controller="http://playerstage.sourceforge.net/gazebo/xmlschema/#controller" xmlns:interface="http://playerstage.sourceforge.net/gazebo/xmlschema/#interface" xmlns:sensor="http://playerstage.sourceforge.net/gazebo/xmlschema/#sensor" xmlns:xacro="http://www.ros.org/wiki/xacro">
  <!-- common xacro -->
  <material name="body_main">
    <color rgba="1.0 0.0 0.0 1.0"/>
  </material>
  <material name="body_sub">
    <color rgba="0.33 0.33 0.33 1.0"/>
  </material>
  <material name="wheel">
    <color rgba="0.2 0.2 0.2 1.0"/>
  </material>
  <material name="black">
    <color rgba="0.1 0.1 0.1 1.0"/>
  </material>
  <material name="tablet">
    <color rgba="0.1 0.1 0.2 1.0"/>
  </material>
  <!-- links and joints -->
  <!-- constant -->
  <!-- constant -->
  <!-- create robot -->
  <link name="hsrb/base_link">
    <visual>
      <geometry>
        <mesh filename="package://tmc_hsrb_description/meshes/base_v0/base.dae"/>
      </geometry>
      <material name="body_main"/>
    </visual>
    <visual>
      <geometry>
        <mesh filename="package://tmc_hsrb_description/meshes/base_v0/body.dae"/>
      </geometry>
      <material name="body_main"/>
    </visual>
    <visual>
      <geometry>
        <mesh filename="package://tmc_hsrb_description/meshes/base_v0/torso_base.dae"/>
      </geometry>
      <material name="body_sub"/>
    </visual>
    <collision>
      <geometry>
        <mesh filename="package://tmc_hsrb_description/meshes/base_v0/base.stl"/>
      </geometry>
      <material name="body_sub"/>
    </collision>
  </link>
  <joint name="hsrb/base_body_joint" type="fixed">
    <parent link="hsrb/base_link"/>
    <child link="hsrb/base_body_link"/>
  </joint>
  <link name="hsrb/base_body_link">
    <inertial>
      <mass value="11.017971"/>
      <origin xyz="-0.025978 -0.005498 0.17633"/>
      <inertia ixx="0.3742" ixy="0.000434172172" ixz="0.03088" iyy="0.3436" iyz="0.01775" izz="0.1509"/>
    </inertial>
  </link>
  <joint name="hsrb/base_roll_joint" type="continuous">
    <origin rpy="0.0 0.0 0.0" xyz="0.0 0.0 0.0"/>
    <axis xyz="0.0 0.0 1.0"/>
    <limit effort="1000.0" velocity="1.0"/>
    <parent link="hsrb/base_body_link"/>
    <child link="hsrb/base_roll_link"/>
  </joint>
  <link name="hsrb/base_roll_link">
    <inertial>
      <origin xyz="-0.01948200 0.00219100 0.07101300"/>
      <mass value="10.239419"/>
      <inertia ixx="0.07671000" ixy="-0.01005000" ixz="0.00174900" iyy="0.09057000" iyz="0.00154900" izz="0.14500000"/>
    </inertial>
  </link>
  <joint name="hsrb/right_drive_wheel_joint" type="continuous">
    <origin rpy="0.0 0.0 0.0" xyz="-0.073                 -0.1275                 0.04"/>
    <axis xyz="0.0 1.0 0.0"/>
    <limit effort="1000.0" velocity="10.0"/>
    <parent link="hsrb/base_roll_link"/>
    <child link="hsrb/right_drive_wheel_link"/>
  </joint>
  <link name="hsrb/right_drive_wheel_link">
    <visual>
      <origin rpy="1.5707963268 0.0 0.0" xyz="0.0 0.0 0.0"/>
      <geometry>
        <cylinder length="0.03" radius="0.04"/>
      </geometry>
      <material name="wheel"/>
    </visual>
    <collision>
      <origin rpy="1.5707963268 0.0 0.0" xyz="0.0 0.0 0.0"/>
      <geometry>
        <cylinder length="0.03" radius="0.04"/>
      </geometry>
      <material name="wheel"/>
    </collision>
    <inertial>
      <mass value="0.1"/>
      <origin xyz="0 0 0"/>
      <inertia ixx="0.001" ixy="0" ixz="0" iyy="0.001" iyz="0" izz="0.001"/>
    </inertial>
  </link>
  <joint name="hsrb/left_drive_wheel_joint" type="continuous">
    <origin rpy="0.0 0.0 0.0" xyz="-0.073                 0.1275                 0.04"/>
    <axis xyz="0.0 1.0 0.0"/>
    <limit effort="1000.0" velocity="10.0"/>
    <parent link="hsrb/base_roll_link"/>
    <child link="hsrb/left_drive_wheel_link"/>
  </joint>
  <link name="hsrb/left_drive_wheel_link">
    <visual>
      <origin rpy="1.5707963268 0.0 0.0" xyz="0.0 0.0 0.0"/>
      <geometry>
        <cylinder length="0.03" radius="0.04"/>
      </geometry>
      <material name="wheel"/>
    </visual>
    <collision>
      <origin rpy="1.5707963268 0.0 0.0" xyz="0.0 0.0 0.0"/>
      <geometry>
        <cylinder length="0.03" radius="0.04"/>
      </geometry>
      <material name="wheel"/>
    </collision>
    <inertial>
      <mass value="0.1"/>
      <origin xyz="0 0 0"/>
      <inertia ixx="0.001" ixy="0" ixz="0" iyy="0.001" iyz="0" izz="0.001"/>
    </inertial>
  </link>
  <joint name="hsrb/right_passive_wheel_x_joint" type="continuous">
    <origin rpy="0.0 0.0 0.0" xyz="0.145                 -0.04                 0.03"/>
    <axis xyz="1.0 0.0 0.0"/>
    <limit effort="1000.0" velocity="100.0"/>
    <parent link="hsrb/base_roll_link"/>
    <child link="hsrb/right_passive_wheel_x_frame"/>
  </joint>
  <link name="hsrb/right_passive_wheel_x_frame">
    <inertial>
      <mass value="0.3"/>
      <origin xyz="0 0 0"/>
      <inertia ixx="0.001" ixy="0" ixz="0" iyy="0.001" iyz="0" izz="0.001"/>
    </inertial>
  </link>
  <joint name="hsrb/right_passive_wheel_y_joint" type="continuous">
    <axis xyz="0.0 1.0 0.0"/>
    <limit effort="1000.0" velocity="100.0"/>
    <parent link="hsrb/right_passive_wheel_x_frame"/>
    <child link="hsrb/right_passive_wheel_y_frame"/>
  </joint>
  <link name="hsrb/right_passive_wheel_y_frame">
    <inertial>
      <mass value="0.3"/>
      <origin xyz="0 0 0"/>
      <inertia ixx="0.001" ixy="0" ixz="0" iyy="0.001" iyz="0" izz="0.001"/>
    </inertial>
  </link>
  <joint name="hsrb/right_passive_wheel_z_joint" type="continuous">
    <axis xyz="0.0 0.0 1.0"/>
    <limit effort="1000.0" velocity="100.0"/>
    <parent link="hsrb/right_passive_wheel_y_frame"/>
    <child link="hsrb/right_passive_wheel_z_link"/>
  </joint>
  <link name="hsrb/right_passive_wheel_z_link">
    <visual>
      <geometry>
        <sphere radius="0.03"/>
      </geometry>
      <material name="wheel"/>
    </visual>
    <collision>
      <geometry>
        <sphere radius="0.03"/>
      </geometry>
      <material name="wheel"/>
    </collision>
    <inertial>
      <mass value="0.3"/>
      <origin xyz="0 0 0"/>
      <inertia ixx="0.001" ixy="0" ixz="0" iyy="0.001" iyz="0" izz="0.001"/>
    </inertial>
  </link>
  <joint name="hsrb/left_passive_wheel_x_joint" type="continuous">
    <origin rpy="0.0 0.0 0.0" xyz="0.145                 0.04                 0.03"/>
    <axis xyz="1.0 0.0 0.0"/>
    <limit effort="1000.0" velocity="100.0"/>
    <parent link="hsrb/base_roll_link"/>
    <child link="hsrb/left_passive_wheel_x_frame"/>
  </joint>
  <link name="hsrb/left_passive_wheel_x_frame">
    <inertial>
      <mass value="0.3"/>
      <origin xyz="0 0 0"/>
      <inertia ixx="0.001" ixy="0" ixz="0" iyy="0.001" iyz="0" izz="0.001"/>
    </inertial>
  </link>
  <joint name="hsrb/left_passive_wheel_y_joint" type="continuous">
    <axis xyz="0.0 1.0 0.0"/>
    <limit effort="1000.0" velocity="100.0"/>
    <parent link="hsrb/left_passive_wheel_x_frame"/>
    <child link="hsrb/left_passive_wheel_y_frame"/>
  </joint>
  <link name="hsrb/left_passive_wheel_y_frame">
    <inertial>
      <mass value="0.3"/>
      <origin xyz="0 0 0"/>
      <inertia ixx="0.001" ixy="0" ixz="0" iyy="0.001" iyz="0" izz="0.001"/>
    </inertial>
  </link>
  <joint name="hsrb/left_passive_wheel_z_joint" type="continuous">
    <axis xyz="0.0 0.0 1.0"/>
    <limit effort="1000.0" velocity="100.0"/>
    <parent link="hsrb/left_passive_wheel_y_frame"/>
    <child link="hsrb/left_passive_wheel_z_link"/>
  </joint>
  <link name="hsrb/left_passive_wheel_z_link">
    <visual>
      <geometry>
        <sphere radius="0.03"/>
      </geometry>
      <material name="wheel"/>
    </visual>
    <collision>
      <geometry>
        <sphere radius="0.03"/>
      </geometry>
      <material name="wheel"/>
    </collision>
    <inertial>
      <mass value="0.3"/>
      <origin xyz="0 0 0"/>
      <inertia ixx="0.001" ixy="0" ixz="0" iyy="0.001" iyz="0" izz="0.001"/>
    </inertial>
  </link>
  <joint name="hsrb/base_laser_joint" type="fixed">
    <origin rpy="0.0 0.0 0.0" xyz="0.1375 0.0 0.1895"/>
    <parent link="hsrb/base_link"/>
    <child link="hsrb/base_laser_link"/>
  </joint>
  <link name="hsrb/base_laser_link">
    <visual>
      <geometry>
        <mesh filename="package://tmc_hsrb_description/meshes/sensors/laser.dae"/>
      </geometry>
      <material name="black"/>
    </visual>
    <collision>
      <geometry>
        <mesh filename="package://tmc_hsrb_description/meshes/sensors/laser.stl"/>
      </geometry>
      <material name="black"/>
    </collision>
  </link>
  <gazebo reference="hsrb/base_laser_link">
    <sensor name="hsrb/base_laser" type="ray">
      <pose>0 0 0 0 0 0</pose>
      <update_rate>10.0</update_rate>
      <visualize>false</visualize>
      <ray>
        <scan>
          <horizontal>
            <samples>640</samples>
            <resolution>1</resolution>
            <min_angle>-69.9009100487</min_angle>
            <max_angle>69.9009100487</max_angle>
          </horizontal>
        </scan>
        <range>
          <min>0.08</min>
          <max>10</max>
          <resolution>0.01</resolution>
        </range>
      </ray>
      <plugin filename="libgazebo_ros_laser.so" name="hokuyo_laser">
        <topicName>hsrb/base_scan</topicName>
        <frameName>hsrb/base_laser_link</frameName>
      </plugin>
    </sensor>
  </gazebo>
  <joint name="hsrb/base_imu_joint" type="fixed">
    <origin rpy="3.14159265359 0.0 0.0" xyz="0.0005 0.1296 0.181"/>
    <parent link="hsrb/base_link"/>
    <child link="hsrb/base_imu_link"/>
  </joint>
  <link name="hsrb/base_imu_link"/>
  <gazebo reference="hsrb/base_imu_link">
    <sensor name="hsrb/base_imu" type="imu">
      <update_rate>10.0</update_rate>
      <imu>
        <noise>
          <type>gaussian</type>
          <rate>
            <mean>0.0</mean>
            <stddev>2e-4</stddev>
            <bias_mean>0.0000075</bias_mean>
            <bias_stddev>0.0000008</bias_stddev>
          </rate>
          <accel>
            <mean>0.0</mean>
            <stddev>1.7e-2</stddev>
            <bias_mean>0.1</bias_mean>
            <bias_stddev>0.001</bias_stddev>
          </accel>
        </noise>
      </imu>
    </sensor>
  </gazebo>
  <gazebo>
    <plugin filename="libtmc_gazebo_imu_plugin.so" name="imu_plugin">
      <imuName>hsrb/base_imu</imuName>
      <topicName>hsrb/base_imu</topicName>
      <frameName>hsrb/base_imu_link</frameName>
    </plugin>
  </gazebo>
  <gazebo reference="hsrb/base_link">
    <selfCollide>false</selfCollide>
    <gravity>true</gravity>
    <mu1>0.9</mu1>
    <mu2>0.9</mu2>
  </gazebo>
  <gazebo reference="hsrb/base_body_link">
    <selfCollide>false</selfCollide>
    <gravity>true</gravity>
    <mu1>0.9</mu1>
    <mu2>0.9</mu2>
  </gazebo>
  <gazebo reference="hsrb/base_roll_link">
    <selfCollide>false</selfCollide>
    <gravity>true</gravity>
    <mu1>0.9</mu1>
    <mu2>0.9</mu2>
  </gazebo>
  <gazebo reference="hsrb/right_drive_wheel_link">
    <selfCollide>false</selfCollide>
    <gravity>true</gravity>
    <turnGravityOff>false</turnGravityOff>
    <kp>1000000.0</kp>
    <kd>10.0</kd>
    <mu1>1.0</mu1>
    <mu2>1.0</mu2>
    <fdir1>1 0 0</fdir1>
    <maxVel>1.0</maxVel>
    <minDepth>0.00</minDepth>
  </gazebo>
  <gazebo reference="hsrb/left_drive_wheel_link">
    <selfCollide>false</selfCollide>
    <gravity>true</gravity>
    <turnGravityOff>false</turnGravityOff>
    <kp>1000000.0</kp>
    <kd>10.0</kd>
    <mu1>1.0</mu1>
    <mu2>1.0</mu2>
    <fdir1>1 0 0</fdir1>
    <maxVel>1.0</maxVel>
    <minDepth>0.00</minDepth>
  </gazebo>
  <gazebo reference="hsrb/right_passive_wheel_z_link">
    <selfCollide>false</selfCollide>
    <gravity>true</gravity>
    <turnGravityOff>false</turnGravityOff>
    <kp>1000000.0</kp>
    <kd>10.0</kd>
    <mu1>1.0</mu1>
    <mu2>1.0</mu2>
    <fdir1>1 0 0</fdir1>
    <maxVel>1.0</maxVel>
    <minDepth>0.00</minDepth>
  </gazebo>
  <gazebo reference="hsrb/left_passive_wheel_z_link">
    <selfCollide>false</selfCollide>
    <gravity>true</gravity>
    <turnGravityOff>false</turnGravityOff>
    <kp>1000000.0</kp>
    <kd>10.0</kd>
    <mu1>1.0</mu1>
    <mu2>1.0</mu2>
    <fdir1>1 0 0</fdir1>
    <maxVel>1.0</maxVel>
    <minDepth>0.00</minDepth>
  </gazebo>
  <gazebo reference="hsrb/base_range_sensor_link">
    <selfCollide>false</selfCollide>
    <gravity>true</gravity>
    <mu1>0.9</mu1>
    <mu2>0.9</mu2>
  </gazebo>
  <gazebo reference="hsrb/base_imu_sensor_link">
    <selfCollide>false</selfCollide>
    <gravity>true</gravity>
    <mu1>0.9</mu1>
    <mu2>0.9</mu2>
  </gazebo>
  <transmission name="hsrb/base_roll_joint_trans">
    <type>transmission_interface/SimpleTransmission</type>
    <joint name="hsrb/base_roll_joint"/>
    <actuator name="hsrb/base_roll_joint_motor">
      <hardwareInterface>VelocityJointInterface</hardwareInterface>
      <mechanicalReduction>1</mechanicalReduction>
    </actuator>
  </transmission>
  <transmission name="hsrb/left_drive_wheel_joint_trans">
    <type>transmission_interface/SimpleTransmission</type>
    <joint name="hsrb/left_drive_wheel_joint"/>
    <actuator name="hsrb/left_drive_wheel_joint_motor">
      <hardwareInterface>VelocityJointInterface</hardwareInterface>
      <mechanicalReduction>1</mechanicalReduction>
    </actuator>
  </transmission>
  <transmission name="hsrb/right_drive_wheel_joint_trans">
    <type>transmission_interface/SimpleTransmission</type>
    <joint name="hsrb/right_drive_wheel_joint"/>
    <actuator name="hsrb/right_drive_wheel_joint_motor">
      <hardwareInterface>VelocityJointInterface</hardwareInterface>
      <mechanicalReduction>1</mechanicalReduction>
    </actuator>
  </transmission>
  <joint name="hsrb/torso_lift_joint" type="prismatic">
    <origin rpy="0.0 0.0 0.0" xyz="0.0 0.0 0.752"/>
    <!-- <origin xyz="0.0 0.0 0.752" rpy="0.0 0.0 0.0" /> -->
    <axis xyz="0.0 0.0 1.0"/>
    <limit effort="100.0" lower="0.0" upper="0.345" velocity="0.1"/>
    <parent link="hsrb/base_body_link"/>
    <child link="hsrb/torso_lift_link"/>
    <mimic joint="hsrb/arm_lift_joint" multiplier="0.5"/>
  </joint>
  <link name="hsrb/torso_lift_link">
    <inertial>
      <mass value="3.420779"/>
      <origin xyz="-0.051142 0.003454 -0.2905"/>
      <inertia ixx="0.1045" ixy="-0.000460884801" ixz="0.000101130383" iyy="0.105" iyz="0.002941" izz="0.01284"/>
    </inertial>
    <visual>
      <geometry>
        <mesh filename="package://tmc_hsrb_description/meshes/torso_v0/torso.dae"/>
      </geometry>
      <material name="body_sub"/>
    </visual>
    <collision>
      <geometry>
        <mesh filename="package://tmc_hsrb_description/meshes/torso_v0/torso.stl"/>
      </geometry>
      <material name="body_sub"/>
    </collision>
  </link>
  <gazebo reference="hsrb/torso_lift_link">
    <selfCollide>false</selfCollide>
    <gravity>true</gravity>
    <mu1>0.9</mu1>
    <mu2>0.9</mu2>
  </gazebo>
  <gazebo_joint name="hsrb/torso_lift_joint"/>
  <gazebo>
    <plugin filename="libtmc_gazebo_mimic_plugin.so" name="torso_mimic_plugin">
      <joint>hsrb/torso_lift_joint</joint>
      <mimicJoint>hsrb/arm_lift_joint</mimicJoint>
      <multiplier>0.5</multiplier>
      <p>900.0</p>
      <i>200.0</i>
      <d>100.0</d>
      <i_clamp>200</i_clamp>
    </plugin>
  </gazebo>
  <transmission name="hsrb/torso_lift_joint_trans">
    <type>transmission_interface/SimpleTransmission</type>
    <joint name="hsrb/torso_lift_joint"/>
    <actuator name="hsrb/torso_lift_joint_motor">
      <hardwareInterface>EffortJointInterface</hardwareInterface>
      <mechanicalReduction>1</mechanicalReduction>
    </actuator>
  </transmission>
  <joint name="hsrb/head_pan_joint" type="revolute">
    <origin rpy="0.0 0.0 0.0" xyz="0.0 0.0 0.0"/>
    <axis xyz="0.0 0.0 1.0"/>
    <limit effort="100.0" lower="-3.84" upper="2.09" velocity="1.0"/>
    <parent link="hsrb/torso_lift_link"/>
    <child link="hsrb/head_pan_link"/>
  </joint>
  <link name="hsrb/head_pan_link">
    <inertial>
      <mass value="0.571903"/>
      <origin xyz="0.001724 -0.001969 -0.028886"/>
      <inertia ixx="0.0009711421" ixy="0.00006179487" ixz="-0.000113923121" iyy="0.00065335493" iyz="0.000069036305" izz="0.000765202576"/>
    </inertial>
    <visual>
      <geometry>
        <mesh filename="package://tmc_hsrb_description/meshes/head_v0/head_pan.dae"/>
      </geometry>
      <material name="body_main"/>
    </visual>
    <collision>
      <geometry>
        <mesh filename="package://tmc_hsrb_description/meshes/head_v0/head_pan.stl"/>
      </geometry>
      <material name="body_main"/>
    </collision>
  </link>
  <joint name="hsrb/head_tilt_joint" type="revolute">
    <origin rpy="0.0 0.0 0.0" xyz="0.02 0.0 0.0"/>
    <axis xyz="0.0 -1.0 0.0"/>
    <limit effort="100.0" lower="-1.57" upper="0.52" velocity="1.0"/>
    <parent link="hsrb/head_pan_link"/>
    <child link="hsrb/head_tilt_link"/>
  </joint>
  <link name="hsrb/head_tilt_link">
    <inertial>
      <mass value="2.123802"/>
      <origin xyz="-0.055376 -0.002436 0.117733"/>
      <inertia ixx="0.01941" ixy="-0.000138091054" ixz="0.005035" iyy="0.01498" iyz="0.000087492537" izz="0.01167"/>
    </inertial>
    <visual>
      <geometry>
        <mesh filename="package://tmc_hsrb_description/meshes/head_v0/head_upper.dae"/>
      </geometry>
      <material name="body_sub"/>
    </visual>
    <visual>
      <geometry>
        <mesh filename="package://tmc_hsrb_description/meshes/head_v0/head_tilt.dae"/>
      </geometry>
      <material name="body_main"/>
    </visual>
    <visual>
      <geometry>
        <mesh filename="package://tmc_hsrb_description/meshes/head_v0/tablet_base.dae"/>
      </geometry>
      <material name="body_sub"/>
    </visual>
    <visual>
      <geometry>
        <mesh filename="package://tmc_hsrb_description/meshes/head_v0/tablet.dae"/>
      </geometry>
      <material name="tablet"/>
    </visual>
    <collision>
      <geometry>
        <mesh filename="package://tmc_hsrb_description/meshes/head_v0/head.stl"/>
      </geometry>
      <material name="body_main"/>
    </collision>
    <collision>
      <geometry>
        <mesh filename="package://tmc_hsrb_description/meshes/head_v0/tablet.stl"/>
      </geometry>
      <material name="tablet"/>
    </collision>
  </link>
  <joint name="hsrb/head_left_camera_joint" type="fixed">
    <origin rpy="0 0 0" xyz="0.02 0.07 0.061"/>
    <parent link="hsrb/head_tilt_link"/>
    <child link="hsrb/head_left_camera_link"/>
  </joint>
  <link name="hsrb/head_left_camera_link">
    <visual>
      <origin rpy="-1.5707963268 0.0 -1.5707963268" xyz="0 0 0"/>
      <geometry>
        <mesh filename="package://tmc_hsrb_description/meshes/sensors/head_camera.dae"/>
      </geometry>
      <material name="black"/>
    </visual>
  </link>
  <gazebo reference="hsrb/head_left_camera_link">
    <sensor name="hsrb/head_left_camera" type="camera">
      <update_rate>10.0</update_rate>
      <camera name="hsrb/head_left_camera">
        <horizontal_fov>1.3962634</horizontal_fov>
        <image>
          <width>320</width>
          <height>240</height>
          <format>R8G8B8</format>
        </image>
        <clip>
          <near>0.05</near>
          <far>100</far>
        </clip>
        <noise>
          <type>gaussian</type>
          <!-- Noise is sampled independently per pixel on each frame.
                             That pixel's noise value is added to each of its color
                             channels, which at that point lie in the range [0,1]. -->
          <mean>0.0</mean>
          <stddev>0.007</stddev>
        </noise>
      </camera>
      <plugin filename="libgazebo_ros_camera.so" name="camera_controller">
        <alwaysOn>0</alwaysOn>
        <updateRate>0.0</updateRate>
        <cameraName>hsrb/head_left_camera</cameraName>
        <imageTopicName>image_raw</imageTopicName>
        <cameraInfoTopicName>camera_info</cameraInfoTopicName>
        <frameName>hsrb/head_left_camera_link</frameName>
        <hackBaseline>0.07</hackBaseline>
        <distortionK1>0.0</distortionK1>
        <distortionK2>0.0</distortionK2>
        <distortionK3>0.0</distortionK3>
        <distortionT1>0.0</distortionT1>
        <distortionT2>0.0</distortionT2>
      </plugin>
    </sensor>
  </gazebo>
  <joint name="hsrb/head_right_camera_joint" type="fixed">
    <origin rpy="0 0 0" xyz="0.02 -0.07 0.061"/>
    <parent link="hsrb/head_tilt_link"/>
    <child link="hsrb/head_right_camera_link"/>
  </joint>
  <link name="hsrb/head_right_camera_link">
    <visual>
      <origin rpy="-1.5707963268 0.0 -1.5707963268" xyz="0 0 0"/>
      <geometry>
        <mesh filename="package://tmc_hsrb_description/meshes/sensors/head_camera.dae"/>
      </geometry>
      <material name="black"/>
    </visual>
  </link>
  <gazebo reference="hsrb/head_right_camera_link">
    <sensor name="hsrb/head_right_camera" type="camera">
      <update_rate>10.0</update_rate>
      <camera name="hsrb/head_right_camera">
        <horizontal_fov>1.3962634</horizontal_fov>
        <image>
          <width>320</width>
          <height>240</height>
          <format>R8G8B8</format>
        </image>
        <clip>
          <near>0.05</near>
          <far>100</far>
        </clip>
        <noise>
          <type>gaussian</type>
          <!-- Noise is sampled independently per pixel on each frame.
                             That pixel's noise value is added to each of its color
                             channels, which at that point lie in the range [0,1]. -->
          <mean>0.0</mean>
          <stddev>0.007</stddev>
        </noise>
      </camera>
      <plugin filename="libgazebo_ros_camera.so" name="camera_controller">
        <alwaysOn>0</alwaysOn>
        <updateRate>0.0</updateRate>
        <cameraName>hsrb/head_right_camera</cameraName>
        <imageTopicName>image_raw</imageTopicName>
        <cameraInfoTopicName>camera_info</cameraInfoTopicName>
        <frameName>hsrb/head_right_camera_link</frameName>
        <hackBaseline>0.07</hackBaseline>
        <distortionK1>0.0</distortionK1>
        <distortionK2>0.0</distortionK2>
        <distortionK3>0.0</distortionK3>
        <distortionT1>0.0</distortionT1>
        <distortionT2>0.0</distortionT2>
      </plugin>
    </sensor>
  </gazebo>
  <joint name="hsrb/head_center_camera_joint" type="fixed">
    <origin rpy="0 0 0" xyz="0.0195 0.0 0.061"/>
    <parent link="hsrb/head_tilt_link"/>
    <child link="hsrb/head_center_camera_link"/>
  </joint>
  <link name="hsrb/head_center_camera_link"/>
  <gazebo reference="hsrb/head_center_camera_link">
    <sensor name="hsrb/head_center_camera" type="camera">
      <update_rate>10.0</update_rate>
      <camera name="hsrb/head_center_camera">
        <horizontal_fov>1.3962634</horizontal_fov>
        <image>
          <width>320</width>
          <height>240</height>
          <format>R8G8B8</format>
        </image>
        <clip>
          <near>0.05</near>
          <far>100</far>
        </clip>
        <noise>
          <type>gaussian</type>
          <!-- Noise is sampled independently per pixel on each frame.
                             That pixel's noise value is added to each of its color
                             channels, which at that point lie in the range [0,1]. -->
          <mean>0.0</mean>
          <stddev>0.007</stddev>
        </noise>
      </camera>
      <plugin filename="libgazebo_ros_camera.so" name="camera_controller">
        <alwaysOn>0</alwaysOn>
        <updateRate>0.0</updateRate>
        <cameraName>hsrb/head_center_camera</cameraName>
        <imageTopicName>image_raw</imageTopicName>
        <cameraInfoTopicName>camera_info</cameraInfoTopicName>
        <frameName>hsrb/head_center_camera_link</frameName>
        <hackBaseline>0.07</hackBaseline>
        <distortionK1>0.0</distortionK1>
        <distortionK2>0.0</distortionK2>
        <distortionK3>0.0</distortionK3>
        <distortionT1>0.0</distortionT1>
        <distortionT2>0.0</distortionT2>
      </plugin>
    </sensor>
  </gazebo>
  <joint name="hsrb/head_depth_camera_joint" type="fixed">
    <origin rpy="0 0 0" xyz="-0.079796 0.022 0.215172"/>
    <parent link="hsrb/head_tilt_link"/>
    <child link="hsrb/head_depth_camera_link"/>
  </joint>
  <link name="hsrb/head_depth_camera_link">
    <visual>
      <origin rpy="-1.5707963268 0.0 -1.5707963268" xyz="0 0 0"/>
      <geometry>
        <mesh filename="package://tmc_hsrb_description/meshes/sensors/xtion.dae"/>
      </geometry>
      <material name="black"/>
    </visual>
    <collision>
      <origin rpy="-1.5707963268 0.0 -1.5707963268" xyz="0 0 0"/>
      <geometry>
        <mesh filename="package://tmc_hsrb_description/meshes/sensors/xtion.stl"/>
      </geometry>
      <material name="black"/>
    </collision>
  </link>
  <joint name="hsrb/head_depth_camera_pointcloud_frame_joint" type="fixed">
    <origin rpy="-1.5707963268 0.0 -1.5707963268" xyz="0 0 0"/>
    <parent link="hsrb/head_depth_camera_link"/>
    <child link="hsrb/head_depth_camera_pointcloud_frame"/>
  </joint>
  <link name="hsrb/head_depth_camera_pointcloud_frame"/>
  <gazebo reference="hsrb/head_depth_camera_link">
    <sensor name="openni_camera_camera" type="depth">
      <always_on>0</always_on>
      <visualize>true</visualize>
      <camera>
        <horizontal_fov>1.047</horizontal_fov>
        <image>
          <width>320</width>
          <height>240</height>
          <format>R8G8B8</format>
        </image>
        <depth_camera> </depth_camera>
        <clip>
          <near>0.1</near>
          <far>100</far>
        </clip>
      </camera>
      <plugin filename="libgazebo_ros_openni_kinect.so" name="camera_controller">
        <alwaysOn>true</alwaysOn>
        <updateRate>10.0</updateRate>
        <cameraName>hsrb/head_depth_camera</cameraName>
        <frameName>hsrb/head_depth_camera_pointcloud_frame</frameName>
        <imageTopicName>/hsrb/head_depth_camera/rgb/image_raw</imageTopicName>
        <depthImageTopicName>/hsrb/head_depth_camera/depth/image_raw</depthImageTopicName>
        <pointCloudTopicName>/hsrb/head_depth_camera/depth/points</pointCloudTopicName>
        <cameraInfoTopicName>/hsrb/head_depth_camera/rgb/camera_info</cameraInfoTopicName>
        <depthImageCameraInfoTopicName>/hsrb/head_depth_camera/depth/camera_info</depthImageCameraInfoTopicName>
        <pointCloudCutoff>0.4</pointCloudCutoff>
        <hackBaseline>0.0</hackBaseline>
        <distortionK1>0.0</distortionK1>
        <distortionK2>0.0</distortionK2>
        <distortionK3>0.0</distortionK3>
        <distortionT1>0.0</distortionT1>
        <distortionT2>0.0</distortionT2>
        <CxPrime>0.0</CxPrime>
        <Cx>0.0</Cx>
        <Cy>0.0</Cy>
        <focalLength>0.0</focalLength>
      </plugin>
    </sensor>
  </gazebo>
  <gazebo reference="hsrb/head_pan_link">
    <selfCollide>false</selfCollide>
    <gravity>true</gravity>
    <mu1>0.9</mu1>
    <mu2>0.9</mu2>
  </gazebo>
  <gazebo reference="hsrb/head_tilt_link">
    <selfCollide>false</selfCollide>
    <gravity>true</gravity>
    <mu1>0.9</mu1>
    <mu2>0.9</mu2>
  </gazebo>
  <gazebo reference="hsrb/head_left_camera_link">
    <selfCollide>false</selfCollide>
    <gravity>true</gravity>
    <mu1>0.9</mu1>
    <mu2>0.9</mu2>
  </gazebo>
  <gazebo reference="hsrb/head_right_camera_link">
    <selfCollide>false</selfCollide>
    <gravity>true</gravity>
    <mu1>0.9</mu1>
    <mu2>0.9</mu2>
  </gazebo>
  <gazebo reference="hsrb/head_center_camera_link">
    <selfCollide>false</selfCollide>
    <gravity>true</gravity>
    <mu1>0.9</mu1>
    <mu2>0.9</mu2>
  </gazebo>
  <gazebo reference="hsrb/head_xtion_link">
    <selfCollide>false</selfCollide>
    <gravity>true</gravity>
    <mu1>0.9</mu1>
    <mu2>0.9</mu2>
  </gazebo>
  <gazebo_joint name="hsrb/head_pan_joint"/>
  <gazebo_joint name="hsrb/head_tilt_joint"/>
  <transmission name="hsrb/head_pan_joint_trans">
    <type>transmission_interface/SimpleTransmission</type>
    <joint name="hsrb/head_pan_joint"/>
    <actuator name="hsrb/head_pan_joint_motor">
      <hardwareInterface>EffortJointInterface</hardwareInterface>
      <mechanicalReduction>1</mechanicalReduction>
    </actuator>
  </transmission>
  <transmission name="hsrb/head_tilt_joint_trans">
    <type>transmission_interface/SimpleTransmission</type>
    <joint name="hsrb/head_tilt_joint"/>
    <actuator name="hsrb/head_tilt_joint_motor">
      <hardwareInterface>EffortJointInterface</hardwareInterface>
      <mechanicalReduction>1</mechanicalReduction>
    </actuator>
  </transmission>
  <joint name="hsrb/arm_lift_joint" type="prismatic">
    <origin rpy="0.0 0.0 0.0" xyz="0.0 0.0 0.340"/>
    <axis xyz="0.0 0.0 1.0"/>
    <limit effort="100.0" lower="0.0" upper="0.69" velocity="0.2"/>
    <parent link="hsrb/base_body_link"/>
    <child link="hsrb/arm_lift_link"/>
  </joint>
  <link name="hsrb/arm_lift_link">
    <inertial>
      <mass value="1.275819"/>
      <origin xyz="0.051549 0.042438 -0.064145"/>
      <inertia ixx="0.004633" ixy="0.000475272668" ixz="-0.002403" iyy="0.008065" iyz="-0.000100268629" izz="0.007672"/>
    </inertial>
    <visual>
      <geometry>
        <mesh filename="package://tmc_hsrb_description/meshes/arm_v0/shoulder.dae"/>
      </geometry>
      <material name="body_sub"/>
    </visual>
    <collision>
      <geometry>
        <mesh filename="package://tmc_hsrb_description/meshes/arm_v0/shoulder.stl"/>
      </geometry>
      <material name="body_sub"/>
    </collision>
  </link>
  <joint name="hsrb/arm_flex_joint" type="revolute">
    <origin rpy="0.0 0.0 0.0" xyz="0.141 0.078 0.0"/>
    <axis xyz="0.0 -1.0 0.0"/>
    <limit effort="100.0" lower="-2.62" upper="0.0" velocity="1.2"/>
    <parent link="hsrb/arm_lift_link"/>
    <child link="hsrb/arm_flex_link"/>
  </joint>
  <link name="hsrb/arm_flex_link">
    <inertial>
      <mass value="1.339295"/>
      <origin xyz="0.000632 0.006404 0.118529"/>
      <inertia ixx="7.528" ixy="-0.000020284207" ixz="-0.000022947194" iyy="0.007102" iyz="-0.000091796075" izz="0.001552"/>
    </inertial>
    <visual>
      <geometry>
        <mesh filename="package://tmc_hsrb_description/meshes/arm_v0/arm_flex.dae"/>
      </geometry>
      <material name="body_main"/>
    </visual>
    <collision>
      <geometry>
        <mesh filename="package://tmc_hsrb_description/meshes/arm_v0/arm_flex.stl"/>
      </geometry>
      <material name="body_main"/>
    </collision>
  </link>
  <joint name="hsrb/arm_roll_joint" type="revolute">
    <origin rpy="0.0 0.0 0.0" xyz="0.005 0.0 0.345"/>
    <axis xyz="0.0 0.0 1.0"/>
    <limit effort="100.0" lower="-2.09" upper="3.84" velocity="2.0"/>
    <parent link="hsrb/arm_flex_link"/>
    <child link="hsrb/arm_roll_link"/>
  </joint>
  <link name="hsrb/arm_roll_link">
    <inertial>
      <mass value="0.247936"/>
      <origin xyz="-0.006927 0.002039 -0.064837"/>
      <inertia ixx="0.004267" ixy="-0.000018322199" ixz="0.000017984455" iyy="0.000780923828" iyz="-0.00001392334" izz="0.00412"/>
    </inertial>
    <visual>
      <geometry>
        <mesh filename="package://tmc_hsrb_description/meshes/arm_v0/arm_roll.dae"/>
      </geometry>
      <material name="body_main"/>
    </visual>
    <collision>
      <geometry>
        <mesh filename="package://tmc_hsrb_description/meshes/arm_v0/arm_roll.stl"/>
      </geometry>
      <material name="body_main"/>
    </collision>
  </link>
  <xacro:hsrb_arm_gazebo robot_name="hsrb"/>
  <transmission name="hsrb/arm_lift_joint_trans">
    <type>transmission_interface/SimpleTransmission</type>
    <joint name="hsrb/arm_lift_joint"/>
    <actuator name="hsrb/arm_lift_joint_motor">
      <hardwareInterface>EffortJointInterface</hardwareInterface>
      <mechanicalReduction>1</mechanicalReduction>
    </actuator>
  </transmission>
  <transmission name="hsrb/arm_flex_joint_trans">
    <type>transmission_interface/SimpleTransmission</type>
    <joint name="hsrb/arm_flex_joint"/>
    <actuator name="hsrb/arm_flex_joint_motor">
      <hardwareInterface>EffortJointInterface</hardwareInterface>
      <mechanicalReduction>1</mechanicalReduction>
    </actuator>
  </transmission>
  <transmission name="hsrb/arm_roll_joint_trans">
    <type>transmission_interface/SimpleTransmission</type>
    <joint name="hsrb/arm_roll_joint"/>
    <actuator name="hsrb/arm_roll_joint_motor">
      <hardwareInterface>EffortJointInterface</hardwareInterface>
      <mechanicalReduction>1</mechanicalReduction>
    </actuator>
  </transmission>
  <joint name="hsrb/wrist_flex_joint" type="revolute">
    <origin rpy="0.0 0.0 0.0" xyz="0.0 0.0 0.0"/>
    <axis xyz="0.0 -1.0 0.0"/>
    <limit effort="100.0" lower="-1.92" upper="1.22" velocity="1.5"/>
    <parent link="hsrb/arm_roll_link"/>
    <child link="hsrb/wrist_flex_link"/>
  </joint>
  <link name="hsrb/wrist_flex_link">
    <inertial>
      <mass value="0.681225"/>
      <origin xyz="0.000131 -0.003929 0.00217"/>
      <inertia ixx="0.000074353558" ixy="0.000000494515" ixz="0.000000022937" iyy="0.000038432887" iyz="-0.00000255576" izz="0.000064680918"/>
    </inertial>
    <visual>
      <geometry>
        <mesh filename="package://tmc_hsrb_description/meshes/wrist_v0/wrist_flex.dae"/>
      </geometry>
      <material name="body_sub"/>
    </visual>
    <visual>
      <origin rpy="0.0 0.0 0.0" xyz="0.0 0.0 0.04"/>
      <geometry>
        <cylinder length="0.02" radius="0.017"/>
      </geometry>
      <material name="body_sub"/>
    </visual>
    <collision>
      <origin rpy="0.0 0.0 0.0" xyz="0.0 0.0 0.03"/>
      <geometry>
        <cylinder length="0.04" radius="0.017"/>
      </geometry>
      <material name="body_sub"/>
    </collision>
  </link>
  <joint name="hsrb/wrist_roll_joint" type="revolute">
    <origin rpy="0.0 0.0 0.0" xyz="0.0 0.0 0.0"/>
    <axis xyz="0.0 0.0 1.0"/>
    <limit effort="100.0" lower="-3.84" upper="2.09" velocity="1.5"/>
    <parent link="hsrb/wrist_flex_link"/>
    <child link="hsrb/wrist_roll_link"/>
  </joint>
  <link name="hsrb/wrist_roll_link">
    <inertial>
      <mass value="0.761692"/>
      <origin xyz="-0.001416 -0.001547 0.081689"/>
      <inertia ixx="0.000805633819" ixy="-0.000014431758" ixz="0.000028204659" iyy="0.000768077165" iyz="0.000022460226" izz="0.000453406611"/>
    </inertial>
    <visual>
      <geometry>
        <mesh filename="package://tmc_hsrb_description/meshes/wrist_v0/wrist_roll.dae"/>
      </geometry>
      <material name="body_main"/>
    </visual>
    <collision>
      <geometry>
        <mesh filename="package://tmc_hsrb_description/meshes/wrist_v0/wrist_roll.stl"/>
      </geometry>
      <material name="body_main"/>
    </collision>
  </link>
  <joint name="hsrb/wrist_ft_sensor_joint" type="fixed">
    <origin rpy="3.14159265359 0.0 0.0" xyz="0.0 0.0 0.0735"/>
    <parent link="hsrb/wrist_roll_link"/>
    <child link="hsrb/wrist_ft_sensor_frame"/>
  </joint>
  <link name="hsrb/wrist_ft_sensor_frame"/>
  <gazebo reference="hsrb/wrist_roll_joint">
    <provideFeedback>true</provideFeedback>
  </gazebo>
  <gazebo>
    <plugin filename="libtmc_gazebo_ft_sensor_plugin.so" name="ft_sensor">
      <updateRate>30.0</updateRate>
      <topicName>hsrb/wrist_wrench</topicName>
      <jointName>hsrb/wrist_roll_joint</jointName>
    </plugin>
  </gazebo>
  <gazebo reference="hsrb/wrist_flex_link">
    <selfCollide>false</selfCollide>
    <gravity>true</gravity>
    <mu1>0.9</mu1>
    <mu2>0.9</mu2>
  </gazebo>
  <gazebo reference="hsrb/wrist_roll_link">
    <selfCollide>false</selfCollide>
    <gravity>true</gravity>
    <mu1>0.9</mu1>
    <mu2>0.9</mu2>
  </gazebo>
  <gazebo reference="hsrb/wrist_force_sensor_frame">
    <selfCollide>false</selfCollide>
    <gravity>true</gravity>
    <mu1>0.9</mu1>
    <mu2>0.9</mu2>
  </gazebo>
  <gazebo_joint name="hsrb/wrist_flex_joint"/>
  <gazebo_joint name="hsrb/wrist_roll_joint"/>
  <transmission name="hsrb/wrist_flex_joint_trans">
    <type>transmission_interface/SimpleTransmission</type>
    <joint name="hsrb/wrist_flex_joint"/>
    <actuator name="hsrb/wrist_flex_joint_motor">
      <hardwareInterface>EffortJointInterface</hardwareInterface>
      <mechanicalReduction>1</mechanicalReduction>
    </actuator>
  </transmission>
  <transmission name="hsrb/wrist_roll_joint_trans">
    <type>transmission_interface/SimpleTransmission</type>
    <joint name="hsrb/wrist_roll_joint"/>
    <actuator name="hsrb/wrist_roll_joint_motor">
      <hardwareInterface>EffortJointInterface</hardwareInterface>
      <mechanicalReduction>1</mechanicalReduction>
    </actuator>
  </transmission>
  <joint name="hsrb/hand_palm_joint" type="revolute">
    <origin rpy="0.0 0.0 3.14159265359" xyz="0.012 0.0 0.1405"/>
    <axis xyz="1.0 0.0 0.0"/>
    <limit effort="0.0" lower="0.0" upper="0.0" velocity="0.0"/>
    <parent link="hsrb/wrist_roll_link"/>
    <child link="hsrb/hand_palm_link"/>
  </joint>
  <link name="hsrb/hand_palm_link">
    <visual>
      <geometry>
        <mesh filename="package://tmc_hsrb_description/meshes/hand_v0/palm.dae"/>
      </geometry>
      <material name="body_sub"/>
    </visual>
    <collision>
      <geometry>
        <mesh filename="package://tmc_hsrb_description/meshes/hand_v0/palm.stl"/>
      </geometry>
      <material name="body_sub"/>
    </collision>
    <inertial>
      <mass value="0.247936"/>
      <origin xyz="0 0 0"/>
      <inertia ixx="0.004267" ixy="-0.000018322199" ixz="0.000017984455" iyy="0.000780923828" iyz="-0.00001392334" izz="0.00412"/>
    </inertial>
  </link>
  <joint name="hsrb/left_proximal_joint" type="revolute">
    <origin rpy="0.0 0.0 0.0" xyz="-0.01675 -0.0245 -0.0175"/>
    <axis xyz="1.0 0.0 0.0"/>
    <limit effort="100.0" lower="-0.1" upper="1.24" velocity="1.0"/>
    <parent link="hsrb/hand_palm_link"/>
    <child link="hsrb/left_proximal_link"/>
  </joint>
  <link name="hsrb/left_proximal_link">
    <inertial>
      <mass value="0.043589"/>
      <origin xyz="0.021418 0.00248 0.022688"/>
      <inertia ixx="0.000026033886" ixy="-0.000000144078" ixz="-0.00000198241" iyy="0.000028824811" iyz="-0.000001268421" izz="0.000005135919"/>
    </inertial>
    <visual>
      <geometry>
        <mesh filename="package://tmc_hsrb_description/meshes/hand_v0/left_proximal.dae"/>
      </geometry>
      <material name="body_sub"/>
    </visual>
    <collision>
      <geometry>
        <mesh filename="package://tmc_hsrb_description/meshes/hand_v0/left_proximal.stl"/>
      </geometry>
      <material name="body_sub"/>
    </collision>
  </link>
  <joint name="hsrb/left_distal_joint" type="revolute">
    <origin rpy="0.0 0.0 0.0" xyz="0.0 0.0 0.07"/>
    <axis xyz="1.0 0.0 0.0"/>
    <limit effort="100.0" lower="-1.24" upper="0.1" velocity="1.0"/>
    <parent link="hsrb/left_proximal_link"/>
    <child link="hsrb/left_distal_link"/>
  </joint>
  <link name="hsrb/left_distal_link">
    <inertial>
      <mass value="0.027731"/>
      <origin xyz="0.011116 0.005679 0.017532"/>
      <inertia ixx="0.000004451952" ixy="-0.000000617574" ixz="0.000000503765" iyy="0.000000503765" iyz="-0.000000435048" izz="0.000004456764"/>
    </inertial>
    <visual>
      <geometry>
        <mesh filename="package://tmc_hsrb_description/meshes/hand_v0/left_distal.dae"/>
      </geometry>
      <material name="body_sub"/>
    </visual>
    <collision>
      <geometry>
        <mesh filename="package://tmc_hsrb_description/meshes/hand_v0/left_distal.stl"/>
      </geometry>
      <material name="body_sub"/>
    </collision>
  </link>
  <joint name="hsrb/left_finger_tip_joint" type="fixed">
    <origin rpy="-1.5707963268 0.0 0.0" xyz="0.01675 0.0193 0.0379"/>
    <parent link="hsrb/left_distal_link"/>
    <child link="hsrb/left_finger_tip_frame"/>
  </joint>
  <link name="hsrb/left_finger_tip_frame">
        </link>
  <joint name="hsrb/left_finger_vacuum_joint" type="fixed">
    <origin rpy="0.785398163398 0.0 0.0" xyz="0.00475 -0.011539 0.03322"/>
    <parent link="hsrb/left_distal_link"/>
    <child link="hsrb/left_finger_vacuum_frame"/>
  </joint>
  <link name="hsrb/left_finger_vacuum_frame">
    <visual>
      <origin rpy="0.0 0.0 0.0" xyz="0.0 0.0 -0.01"/>
      <geometry>
        <box size="0.008 0.008 0.02"/>
      </geometry>
      <material name="body_sub"/>
    </visual>
  </link>
  <joint name="hsrb/right_proximal_joint" type="revolute">
    <origin rpy="0.0 0.0 0.0" xyz="-0.01675 0.0245 -0.0175"/>
    <axis xyz="-1.0 0.0 0.0"/>
    <limit effort="100.0" lower="-0.1" upper="1.24" velocity="1.0"/>
    <parent link="hsrb/hand_palm_link"/>
    <child link="hsrb/right_proximal_link"/>
  </joint>
  <link name="hsrb/right_proximal_link">
    <inertial>
      <mass value="0.043956"/>
      <origin xyz="0.013203 0.002096 0.023311"/>
      <inertia ixx="0.00002623664" ixy="0.00000001631" ixz="0.000001281845" iyy="0.000028838232" iyz="-0.000001621709" izz="0.000004957151"/>
    </inertial>
    <visual>
      <geometry>
        <mesh filename="package://tmc_hsrb_description/meshes/hand_v0/right_proximal.dae"/>
      </geometry>
      <material name="body_sub"/>
    </visual>
    <collision>
      <geometry>
        <mesh filename="package://tmc_hsrb_description/meshes/hand_v0/right_proximal.stl"/>
      </geometry>
      <material name="body_sub"/>
    </collision>
  </link>
  <joint name="hsrb/right_distal_joint" type="revolute">
    <origin rpy="0.0 0.0 0.0" xyz="0.0 0.0 0.07"/>
    <axis xyz="-1.0 0.0 0.0"/>
    <limit effort="100.0" lower="-1.24" upper="0.1" velocity="1.0"/>
    <parent link="hsrb/right_proximal_link"/>
    <child link="hsrb/right_distal_link"/>
  </joint>
  <link name="hsrb/right_distal_link">
    <inertial>
      <mass value="0.020927"/>
      <origin xyz="0.014256 -0.008321 0.015591"/>
      <inertia ixx="0.00000307518" ixy="-0.00000004954" ixz="0.000000009481" iyy="0.000004074079" iyz="0.000000843648" izz="0.000002807795"/>
    </inertial>
    <visual>
      <geometry>
        <mesh filename="package://tmc_hsrb_description/meshes/hand_v0/right_distal.dae"/>
      </geometry>
      <material name="body_sub"/>
    </visual>
    <collision>
      <geometry>
        <mesh filename="package://tmc_hsrb_description/meshes/hand_v0/right_distal.stl"/>
      </geometry>
      <material name="body_sub"/>
    </collision>
  </link>
  <joint name="hsrb/right_finger_tip_joint" type="fixed">
    <origin rpy="1.5707963268 0.0 0.0" xyz="0.01675 -0.0193 0.0379"/>
    <parent link="hsrb/right_distal_link"/>
    <child link="hsrb/right_finger_tip_frame"/>
  </joint>
  <link name="hsrb/right_finger_tip_frame"/>
  <joint name="hsrb/hand_camera_joint" type="fixed">
    <origin rpy="3.14159265359 -1.5707963268 0" xyz="0.039 0.0 -0.0045"/>
    <parent link="hsrb/hand_palm_link"/>
    <child link="hsrb/hand_camera_link"/>
  </joint>
  <link name="hsrb/hand_camera_link"/>
  <gazebo reference="hsrb/hand_camera_link">
    <sensor name="hsrb/hand_camera" type="camera">
      <update_rate>10.0</update_rate>
      <camera name="hsrb/hand_camera">
        <horizontal_fov>1.3962634</horizontal_fov>
        <image>
          <width>320</width>
          <height>240</height>
          <format>R8G8B8</format>
        </image>
        <clip>
          <near>0.05</near>
          <far>100</far>
        </clip>
        <noise>
          <type>gaussian</type>
          <!-- Noise is sampled independently per pixel on each frame.
                             That pixel's noise value is added to each of its color
                             channels, which at that point lie in the range [0,1]. -->
          <mean>0.0</mean>
          <stddev>0.007</stddev>
        </noise>
      </camera>
      <plugin filename="libgazebo_ros_camera.so" name="camera_controller">
        <alwaysOn>0</alwaysOn>
        <updateRate>0.0</updateRate>
        <cameraName>hsrb/hand_camera</cameraName>
        <imageTopicName>image_raw</imageTopicName>
        <cameraInfoTopicName>camera_info</cameraInfoTopicName>
        <frameName>hsrb/hand_camera_link</frameName>
        <hackBaseline>0.07</hackBaseline>
        <distortionK1>0.0</distortionK1>
        <distortionK2>0.0</distortionK2>
        <distortionK3>0.0</distortionK3>
        <distortionT1>0.0</distortionT1>
        <distortionT2>0.0</distortionT2>
      </plugin>
    </sensor>
  </gazebo>
  <gazebo reference="hsrb/hand_palm_link">
    <selfCollide>false</selfCollide>
    <gravity>true</gravity>
    <mu1>0.9</mu1>
    <mu2>0.9</mu2>
  </gazebo>
  <gazebo reference="hsrb/hand_camera_link">
    <selfCollide>false</selfCollide>
    <gravity>true</gravity>
    <mu1>0.9</mu1>
    <mu2>0.9</mu2>
  </gazebo>
  <gazebo reference="hsrb/left_proximal_link">
    <selfCollide>false</selfCollide>
    <gravity>true</gravity>
    <mu1>1.0</mu1>
    <mu2>1.0</mu2>
  </gazebo>
  <gazebo reference="hsrb/left_distal_link">
    <selfCollide>false</selfCollide>
    <gravity>true</gravity>
    <mu1>1.0</mu1>
    <mu2>1.0</mu2>
  </gazebo>
  <gazebo reference="hsrb/left_finger_tip_frame">
    <selfCollide>false</selfCollide>
    <gravity>true</gravity>
    <mu1>1.0</mu1>
    <mu2>1.0</mu2>
  </gazebo>
  <gazebo reference="hsrb/left_finger_vacuum_frame">
    <selfCollide>false</selfCollide>
    <gravity>true</gravity>
    <mu1>1.0</mu1>
    <mu2>1.0</mu2>
  </gazebo>
  <gazebo reference="hsrb/right_proximal_link">
    <selfCollide>false</selfCollide>
    <gravity>true</gravity>
    <mu1>1.0</mu1>
    <mu2>1.0</mu2>
  </gazebo>
  <gazebo reference="hsrb/right_distal_link">
    <selfCollide>false</selfCollide>
    <gravity>true</gravity>
    <mu1>1.0</mu1>
    <mu2>1.0</mu2>
  </gazebo>
  <gazebo reference="hsrb/right_finger_tip_frame">
    <selfCollide>false</selfCollide>
    <gravity>true</gravity>
    <mu1>1.0</mu1>
    <mu2>1.0</mu2>
  </gazebo>
  <gazebo reference="hsrb/right_finger_vacuum_frame">
    <selfCollide>false</selfCollide>
    <gravity>true</gravity>
    <mu1>1.0</mu1>
    <mu2>1.0</mu2>
  </gazebo>
  <gazebo_joint name="hsrb/left_proximal_joint"/>
  <gazebo_joint name="hsrb/left_distal_joint"/>
  <gazebo_joint name="hsrb/right_proximal_joint"/>
  <gazebo_joint name="hsrb/right_distal_joint"/>
  <gazebo>
    <gripper name="grasp_hack">
      <grasp_check>
        <attach_steps>1</attach_steps>
        <detach_steps>5</detach_steps>
        <min_contact_count>1</min_contact_count>
      </grasp_check>
      <gripper_link>hsrb/right_distal_link</gripper_link>
      <gripper_link>hsrb/left_distal_link</gripper_link>
      <gripper_link>hsrb/right_proximal_link</gripper_link>
      <gripper_link>hsrb/left_proximal_link</gripper_link>
      <palm_link>hsrb/hand_palm_link</palm_link>
    </gripper>
  </gazebo>
  <transmission name="hsrb/hand_palm_joint_trans">
    <type>transmission_interface/SimpleTransmission</type>
    <joint name="hsrb/hand_palm_joint"/>
    <actuator name="hsrb/hand_palm_joint_motor">
      <hardwareInterface>EffortJointInterface</hardwareInterface>
      <mechanicalReduction>1</mechanicalReduction>
    </actuator>
  </transmission>
  <transmission name="hsrb/left_proximal_joint_trans">
    <type>transmission_interface/SimpleTransmission</type>
    <joint name="hsrb/left_proximal_joint"/>
    <actuator name="hsrb/left_proximal_joint_motor">
      <hardwareInterface>EffortJointInterface</hardwareInterface>
      <mechanicalReduction>1</mechanicalReduction>
    </actuator>
  </transmission>
  <transmission name="hsrb/left_distal_joint_trans">
    <type>transmission_interface/SimpleTransmission</type>
    <joint name="hsrb/left_distal_joint"/>
    <actuator name="hsrb/left_distal_joint_motor">
      <hardwareInterface>EffortJointInterface</hardwareInterface>
      <mechanicalReduction>1</mechanicalReduction>
    </actuator>
  </transmission>
  <transmission name="hsrb/right_proximal_joint_trans">
    <type>transmission_interface/SimpleTransmission</type>
    <joint name="hsrb/right_proximal_joint"/>
    <actuator name="hsrb/right_proximal_joint_motor">
      <hardwareInterface>EffortJointInterface</hardwareInterface>
      <mechanicalReduction>1</mechanicalReduction>
    </actuator>
  </transmission>
  <transmission name="hsrb/right_distal_joint_trans">
    <type>transmission_interface/SimpleTransmission</type>
    <joint name="hsrb/right_distal_joint"/>
    <actuator name="hsrb/right_distal_joint_motor">
      <hardwareInterface>EffortJointInterface</hardwareInterface>
      <mechanicalReduction>1</mechanicalReduction>
    </actuator>
  </transmission>
</robot>
