<?xml version="1.0" ?>
<!-- =================================================================================== -->
<!-- |    This document was autogenerated by xacro from /home/tkmr/prog/qt-rospackages-unreleased/TMC2014/catkin_ws/src/tmc_hsrb_description/robots/beetle/beetle.urdf.xacro | -->
<!-- |    EDITING THIS FILE BY HAND IS NOT RECOMMENDED                                 | -->
<!-- =================================================================================== -->
<robot name="hsr_beetle" xmlns:xacro="http://ros.org/wiki/xacro">
  <!-- include xacro-->
  <material name="body_main">
    <color rgba="1.0 0.0 0.0 1.0"/>
  </material>
  <material name="body_sub">
    <color rgba="0.33 0.33 0.33 1.0"/>
  </material>
  <material name="wheel">
    <color rgba="0.2 0.2 0.2 1.0"/>
  </material>
  <material name="black">
    <color rgba="0.1 0.1 0.1 1.0"/>
  </material>
  <material name="tablet">
    <color rgba="0.1 0.1 0.2 1.0"/>
  </material>
  <!-- constant -->
  <!-- create robot -->
  <link name="hsr_beetle/base_link">
    <visual>
      <geometry>
        <mesh filename="package://tmc_hsrb_description/meshes/beetle/visual/base.dae"/>
      </geometry>
      <material name="body_main"/>
    </visual>
    <visual>
      <geometry>
        <mesh filename="package://tmc_hsrb_description/meshes/beetle/visual/body.dae"/>
      </geometry>
      <material name="body_main"/>
    </visual>
    <visual>
      <geometry>
        <mesh filename="package://tmc_hsrb_description/meshes/beetle/visual/torso_base.dae"/>
      </geometry>
      <material name="body_sub"/>
    </visual>
    <collision>
      <geometry>
        <mesh filename="package://tmc_hsrb_description/meshes/beetle/collision/base.stl"/>
      </geometry>
      <material name="body_sub"/>
    </collision>
  </link>
  <joint name="hsr_beetle/base_body_joint" type="fixed">
    <parent link="hsr_beetle/base_link"/>
    <child link="hsr_beetle/base_body_link"/>
  </joint>
  <link name="hsr_beetle/base_body_link">
    <inertial>
      <mass value="11.017971"/>
      <origin xyz="-0.025978 -0.005498 0.17633"/>
      <inertia ixx="0.3742" ixy="0.000434172172" ixz="0.03088" iyy="0.3436" iyz="0.01775" izz="0.1509"/>
    </inertial>
  </link>
  <joint name="hsr_beetle/base_roll_joint" type="continuous">
    <origin rpy="0.0 0.0 0.0" xyz="0.0 0.0 0.0"/>
    <axis xyz="0.0 0.0 1.0"/>
    <limit effort="100.0" velocity="1.0"/>
    <parent link="hsr_beetle/base_body_link"/>
    <child link="hsr_beetle/base_roll_link"/>
    <limit effort="1.0" velocity="1.0"/>
  </joint>
  <link name="hsr_beetle/base_roll_link">
    <inertial>
      <origin xyz="-0.01948200 0.00219100 0.07101300"/>
      <mass value="10.239419"/>
      <inertia ixx="0.07671000" ixy="-0.01005000" ixz="0.00174900" iyy="0.09057000" iyz="0.00154900" izz="0.14500000"/>
    </inertial>
  </link>
  <joint name="hsr_beetle/right_drive_wheel_joint" type="continuous">
    <origin rpy="0.0 0.0 0.0" xyz="-0.073                    -0.1275                    0.04"/>
    <axis xyz="0.0 1.0 0.0"/>
    <limit effort="100.0" velocity="10.0"/>
    <parent link="hsr_beetle/base_roll_link"/>
    <child link="hsr_beetle/right_drive_wheel_link"/>
  </joint>
  <link name="hsr_beetle/right_drive_wheel_link">
    <visual>
      <origin rpy="1.5707963268 0.0 0.0" xyz="0.0 0.0 0.0"/>
      <geometry>
        <cylinder length="0.03" radius="0.04"/>
      </geometry>
      <material name="wheel"/>
    </visual>
    <collision>
      <origin rpy="1.5707963268 0.0 0.0" xyz="0.0 0.0 0.0"/>
      <geometry>
        <cylinder length="0.03" radius="0.04"/>
      </geometry>
      <material name="wheel"/>
    </collision>
    <inertial>
      <mass value="1"/>
      <origin xyz="0 0 0"/>
      <inertia ixx="1" ixy="0" ixz="0" iyy="1" iyz="0" izz="1"/>
    </inertial>
  </link>
  <joint name="hsr_beetle/left_drive_wheel_joint" type="continuous">
    <origin rpy="0.0 0.0 0.0" xyz="-0.073                    0.1275                    0.04"/>
    <axis xyz="0.0 1.0 0.0"/>
    <limit effort="100.0" velocity="10.0"/>
    <parent link="hsr_beetle/base_roll_link"/>
    <child link="hsr_beetle/left_drive_wheel_link"/>
  </joint>
  <link name="hsr_beetle/left_drive_wheel_link">
    <visual>
      <origin rpy="1.5707963268 0.0 0.0" xyz="0.0 0.0 0.0"/>
      <geometry>
        <cylinder length="0.03" radius="0.04"/>
      </geometry>
      <material name="wheel"/>
    </visual>
    <collision>
      <origin rpy="1.5707963268 0.0 0.0" xyz="0.0 0.0 0.0"/>
      <geometry>
        <cylinder length="0.03" radius="0.04"/>
      </geometry>
      <material name="wheel"/>
    </collision>
    <inertial>
      <mass value="1"/>
      <origin xyz="0 0 0"/>
      <inertia ixx="1" ixy="0" ixz="0" iyy="1" iyz="0" izz="1"/>
    </inertial>
  </link>
  <joint name="hsr_beetle/right_passive_wheel_x_joint" type="continuous">
    <origin rpy="0.0 0.0 0.0" xyz="0.145                    -0.04                    0.03"/>
    <axis xyz="1.0 0.0 0.0"/>
    <limit effort="1000.0" velocity="100.0"/>
    <parent link="hsr_beetle/base_roll_link"/>
    <child link="hsr_beetle/right_passive_wheel_x_frame"/>
  </joint>
  <link name="hsr_beetle/right_passive_wheel_x_frame">
    <inertial>
      <mass value="0.3"/>
      <origin xyz="0 0 0"/>
      <inertia ixx="1" ixy="0" ixz="0" iyy="1" iyz="0" izz="1"/>
    </inertial>
  </link>
  <joint name="hsr_beetle/right_passive_wheel_y_joint" type="continuous">
    <axis xyz="0.0 1.0 0.0"/>
    <limit effort="1000.0" velocity="100.0"/>
    <parent link="hsr_beetle/right_passive_wheel_x_frame"/>
    <child link="hsr_beetle/right_passive_wheel_y_frame"/>
  </joint>
  <link name="hsr_beetle/right_passive_wheel_y_frame">
    <inertial>
      <mass value="0.3"/>
      <origin xyz="0 0 0"/>
      <inertia ixx="1" ixy="0" ixz="0" iyy="1" iyz="0" izz="1"/>
    </inertial>
  </link>
  <joint name="hsr_beetle/right_passive_wheel_z_joint" type="continuous">
    <axis xyz="0.0 0.0 1.0"/>
    <limit effort="1000.0" velocity="100.0"/>
    <parent link="hsr_beetle/right_passive_wheel_y_frame"/>
    <child link="hsr_beetle/right_passive_wheel_z_link"/>
  </joint>
  <link name="hsr_beetle/right_passive_wheel_z_link">
    <visual>
      <geometry>
        <sphere radius="0.03"/>
      </geometry>
      <material name="wheel"/>
    </visual>
    <collision>
      <geometry>
        <sphere radius="0.03"/>
      </geometry>
      <material name="wheel"/>
    </collision>
    <inertial>
      <mass value="0.3"/>
      <origin xyz="0 0 0"/>
      <inertia ixx="1" ixy="0" ixz="0" iyy="1" iyz="0" izz="1"/>
    </inertial>
  </link>
  <joint name="hsr_beetle/left_passive_wheel_x_joint" type="continuous">
    <origin rpy="0.0 0.0 0.0" xyz="0.145                    0.04                    0.03"/>
    <axis xyz="1.0 0.0 0.0"/>
    <limit effort="1000.0" velocity="100.0"/>
    <parent link="hsr_beetle/base_roll_link"/>
    <child link="hsr_beetle/left_passive_wheel_x_frame"/>
  </joint>
  <link name="hsr_beetle/left_passive_wheel_x_frame">
    <inertial>
      <mass value="0.3"/>
      <origin xyz="0 0 0"/>
      <inertia ixx="1" ixy="0" ixz="0" iyy="1" iyz="0" izz="1"/>
    </inertial>
  </link>
  <joint name="hsr_beetle/left_passive_wheel_y_joint" type="continuous">
    <axis xyz="0.0 1.0 0.0"/>
    <limit effort="1000.0" velocity="100.0"/>
    <parent link="hsr_beetle/left_passive_wheel_x_frame"/>
    <child link="hsr_beetle/left_passive_wheel_y_frame"/>
  </joint>
  <link name="hsr_beetle/left_passive_wheel_y_frame">
    <inertial>
      <mass value="0.3"/>
      <origin xyz="0 0 0"/>
      <inertia ixx="1" ixy="0" ixz="0" iyy="1" iyz="0" izz="1"/>
    </inertial>
  </link>
  <joint name="hsr_beetle/left_passive_wheel_z_joint" type="continuous">
    <axis xyz="0.0 0.0 1.0"/>
    <limit effort="1000.0" velocity="100.0"/>
    <parent link="hsr_beetle/left_passive_wheel_y_frame"/>
    <child link="hsr_beetle/left_passive_wheel_z_link"/>
  </joint>
  <link name="hsr_beetle/left_passive_wheel_z_link">
    <visual>
      <geometry>
        <sphere radius="0.03"/>
      </geometry>
      <material name="wheel"/>
    </visual>
    <collision>
      <geometry>
        <sphere radius="0.03"/>
      </geometry>
      <material name="wheel"/>
    </collision>
    <inertial>
      <mass value="0.3"/>
      <origin xyz="0 0 0"/>
      <inertia ixx="1" ixy="0" ixz="0" iyy="1" iyz="0" izz="1"/>
    </inertial>
  </link>
  <joint name="hsr_beetle/base_range_sensor_joint" type="fixed">
    <origin rpy="0.0 0.0 0.0" xyz="0.1375 0.0 0.1895"/>
    <parent link="hsr_beetle/base_link"/>
    <child link="hsr_beetle/base_range_sensor_link"/>
  </joint>
  <link name="hsr_beetle/base_range_sensor_link">
    <visual>
      <geometry>
        <mesh filename="package://tmc_hsrb_description/meshes/beetle/visual/range_sensor.dae"/>
      </geometry>
      <material name="black"/>
    </visual>
    <collision>
      <geometry>
        <mesh filename="package://tmc_hsrb_description/meshes/beetle/collision/range_sensor.stl"/>
      </geometry>
      <material name="black"/>
    </collision>
  </link>
  <joint name="hsr_beetle/base_imu_sensor_joint" type="fixed">
    <origin rpy="3.14159265359 0.0 0.0" xyz="0.0005 0.1296 0.181"/>
    <parent link="hsr_beetle/base_link"/>
    <child link="hsr_beetle/base_imu_sensor_link"/>
  </joint>
  <link name="hsr_beetle/base_imu_sensor_link">
    </link>
  <joint name="hsr_beetle/torso_lift_joint" type="prismatic">
    <origin rpy="0.0 0.0 0.0" xyz="0.0 0.0 0.752"/>
    <!-- <origin xyz="0.0 0.0 0.752" rpy="0.0 0.0 0.0" /> -->
    <axis xyz="0.0 0.0 1.0"/>
    <limit effort="100.0" lower="0.0" upper="0.345" velocity="0.1"/>
    <parent link="hsr_beetle/base_body_link"/>
    <child link="hsr_beetle/torso_lift_link"/>
    <mimic joint="hsr_beetle/arm_lift_joint" multiplier="0.5"/>
  </joint>
  <link name="hsr_beetle/torso_lift_link">
    <inertial>
      <mass value="3.420779"/>
      <origin xyz="-0.051142 0.003454 -0.2905"/>
      <inertia ixx="0.1045" ixy="-0.000460884801" ixz="0.000101130383" iyy="0.105" iyz="0.002941" izz="0.01284"/>
    </inertial>
    <visual>
      <geometry>
        <mesh filename="package://tmc_hsrb_description/meshes/beetle/visual/torso.dae"/>
      </geometry>
      <material name="body_sub"/>
    </visual>
    <collision>
      <geometry>
        <mesh filename="package://tmc_hsrb_description/meshes/beetle/collision/torso.stl"/>
      </geometry>
      <material name="body_sub"/>
    </collision>
  </link>
  <joint name="hsr_beetle/head_pan_joint" type="revolute">
    <origin rpy="0.0 0.0 0.0" xyz="0.0 0.0 0.0"/>
    <axis xyz="0.0 0.0 1.0"/>
    <limit effort="100.0" lower="-3.84" upper="2.09" velocity="1.0"/>
    <parent link="hsr_beetle/torso_lift_link"/>
    <child link="hsr_beetle/head_pan_link"/>
  </joint>
  <link name="hsr_beetle/head_pan_link">
    <inertial>
      <mass value="0.571903"/>
      <origin xyz="0.001724 -0.001969 -0.028886"/>
      <inertia ixx="0.0009711421" ixy="0.00006179487" ixz="-0.000113923121" iyy="0.00065335493" iyz="0.000069036305" izz="0.000765202576"/>
    </inertial>
    <visual>
      <geometry>
        <mesh filename="package://tmc_hsrb_description/meshes/beetle/visual/head_pan.dae"/>
      </geometry>
      <material name="body_main"/>
    </visual>
    <collision>
      <geometry>
        <mesh filename="package://tmc_hsrb_description/meshes/beetle/collision/head_pan.stl"/>
      </geometry>
      <material name="body_main"/>
    </collision>
  </link>
  <joint name="hsr_beetle/head_tilt_joint" type="revolute">
    <origin rpy="0.0 0.0 0.0" xyz="0.02 0.0 0.0"/>
    <axis xyz="0.0 -1.0 0.0"/>
    <limit effort="100.0" lower="-1.57" upper="0.52" velocity="1.0"/>
    <parent link="hsr_beetle/head_pan_link"/>
    <child link="hsr_beetle/head_tilt_link"/>
  </joint>
  <link name="hsr_beetle/head_tilt_link">
    <inertial>
      <mass value="2.123802"/>
      <origin xyz="-0.055376 -0.002436 0.117733"/>
      <inertia ixx="0.01941" ixy="-0.000138091054" ixz="0.005035" iyy="0.01498" iyz="0.000087492537" izz="0.01167"/>
    </inertial>
    <visual>
      <geometry>
        <mesh filename="package://tmc_hsrb_description/meshes/beetle/visual/head_upper.dae"/>
      </geometry>
      <material name="body_sub"/>
    </visual>
    <visual>
      <geometry>
        <mesh filename="package://tmc_hsrb_description/meshes/beetle/visual/head_tilt.dae"/>
      </geometry>
      <material name="body_main"/>
    </visual>
    <visual>
      <geometry>
        <mesh filename="package://tmc_hsrb_description/meshes/beetle/visual/tablet_base.dae"/>
      </geometry>
      <material name="body_sub"/>
    </visual>
    <visual>
      <geometry>
        <mesh filename="package://tmc_hsrb_description/meshes/beetle/visual/tablet.dae"/>
      </geometry>
      <material name="tablet"/>
    </visual>
    <collision>
      <geometry>
        <mesh filename="package://tmc_hsrb_description/meshes/beetle/collision/head.stl"/>
      </geometry>
      <material name="body_main"/>
    </collision>
    <collision>
      <geometry>
        <mesh filename="package://tmc_hsrb_description/meshes/beetle/collision/tablet.stl"/>
      </geometry>
      <material name="tablet"/>
    </collision>
  </link>
  <joint name="hsr_beetle/head_left_camera_joint" type="fixed">
    <origin rpy="0 0 0" xyz="0.02 0.07 0.061"/>
    <parent link="hsr_beetle/head_tilt_link"/>
    <child link="hsr_beetle/head_left_camera_link"/>
  </joint>
  <link name="hsr_beetle/head_left_camera_link">
    <visual>
      <origin rpy="-1.5707963268 0.0 -1.5707963268" xyz="0 0 0"/>
      <geometry>
        <mesh filename="package://tmc_hsrb_description/meshes/beetle/visual/head_camera.dae"/>
      </geometry>
      <material name="black"/>
    </visual>
  </link>
  <joint name="hsr_beetle/head_right_camera_joint" type="fixed">
    <origin rpy="0 0 0" xyz="0.02 -0.07 0.061"/>
    <parent link="hsr_beetle/head_tilt_link"/>
    <child link="hsr_beetle/head_right_camera_link"/>
  </joint>
  <link name="hsr_beetle/head_right_camera_link">
    <visual>
      <origin rpy="-1.5707963268 0.0 -1.5707963268" xyz="0 0 0"/>
      <geometry>
        <mesh filename="package://tmc_hsrb_description/meshes/beetle/visual/head_camera.dae"/>
      </geometry>
      <material name="black"/>
    </visual>
  </link>
  <joint name="hsr_beetle/head_center_camera_joint" type="fixed">
    <origin rpy="0 0 0" xyz="0.0195 0.0 0.061"/>
    <parent link="hsr_beetle/head_tilt_link"/>
    <child link="hsr_beetle/head_center_camera_link"/>
  </joint>
  <link name="hsr_beetle/head_center_camera_link">
    </link>
  <joint name="hsr_beetle/head_xtion_joint" type="fixed">
    <origin rpy="0 0 0" xyz="-0.079796 0.022 0.215172"/>
    <parent link="hsr_beetle/head_tilt_link"/>
    <child link="hsr_beetle/head_xtion_link"/>
  </joint>
  <link name="hsr_beetle/head_xtion_link">
    <visual>
      <origin rpy="-1.5707963268 0.0 -1.5707963268" xyz="0 0 0"/>
      <geometry>
        <mesh filename="package://tmc_hsrb_description/meshes/beetle/visual/xtion.dae"/>
      </geometry>
      <material name="black"/>
    </visual>
    <collision>
      <origin rpy="-1.5707963268 0.0 -1.5707963268" xyz="0 0 0"/>
      <geometry>
        <mesh filename="package://tmc_hsrb_description/meshes/beetle/collision/xtion.stl"/>
      </geometry>
      <material name="black"/>
    </collision>
  </link>
  <joint name="hsr_beetle/head_xtion_cloud_frame_joint" type="fixed">
    <origin rpy="-1.5707963268 0.0 -1.5707963268" xyz="0 0 0"/>
    <parent link="hsr_beetle/head_xtion_link"/>
    <child link="hsr_beetle/head_xtion_cloud_frame"/>
  </joint>
  <link name="hsr_beetle/head_xtion_cloud_frame">
    </link>
  <joint name="hsr_beetle/arm_lift_joint" type="prismatic">
    <origin rpy="0.0 0.0 0.0" xyz="0.0 0.0 0.340"/>
    <axis xyz="0.0 0.0 1.0"/>
    <limit effort="100.0" lower="0.0" upper="0.69" velocity="0.2"/>
    <parent link="hsr_beetle/base_body_link"/>
    <child link="hsr_beetle/arm_lift_link"/>
  </joint>
  <link name="hsr_beetle/arm_lift_link">
    <inertial>
      <mass value="1.275819"/>
      <origin xyz="0.051549 0.042438 -0.064145"/>
      <inertia ixx="0.004633" ixy="0.000475272668" ixz="-0.002403" iyy="0.008065" iyz="-0.000100268629" izz="0.007672"/>
    </inertial>
    <visual>
      <geometry>
        <mesh filename="package://tmc_hsrb_description/meshes/beetle/visual/shoulder.dae"/>
      </geometry>
      <material name="body_sub"/>
    </visual>
    <collision>
      <geometry>
        <mesh filename="package://tmc_hsrb_description/meshes/beetle/collision/shoulder.stl"/>
      </geometry>
      <material name="body_sub"/>
    </collision>
  </link>
  <joint name="hsr_beetle/arm_flex_joint" type="revolute">
    <origin rpy="0.0 0.0 0.0" xyz="0.141 0.078 0.0"/>
    <axis xyz="0.0 -1.0 0.0"/>
    <limit effort="100.0" lower="-2.62" upper="0.0" velocity="1.2"/>
    <parent link="hsr_beetle/arm_lift_link"/>
    <child link="hsr_beetle/arm_flex_link"/>
  </joint>
  <link name="hsr_beetle/arm_flex_link">
    <inertial>
      <mass value="1.339295"/>
      <origin xyz="0.000632 0.006404 0.118529"/>
      <inertia ixx="7.528" ixy="-0.000020284207" ixz="-0.000022947194" iyy="0.007102" iyz="-0.000091796075" izz="0.001552"/>
    </inertial>
    <visual>
      <geometry>
        <mesh filename="package://tmc_hsrb_description/meshes/beetle/visual/arm_flex.dae"/>
      </geometry>
      <material name="body_main"/>
    </visual>
    <collision>
      <geometry>
        <mesh filename="package://tmc_hsrb_description/meshes/beetle/collision/arm_flex.stl"/>
      </geometry>
      <material name="body_main"/>
    </collision>
  </link>
  <joint name="hsr_beetle/arm_roll_joint" type="revolute">
    <origin rpy="0.0 0.0 0.0" xyz="0.005 0.0 0.345"/>
    <axis xyz="0.0 0.0 1.0"/>
    <limit effort="100.0" lower="-2.09" upper="3.84" velocity="2.0"/>
    <parent link="hsr_beetle/arm_flex_link"/>
    <child link="hsr_beetle/arm_roll_link"/>
  </joint>
  <link name="hsr_beetle/arm_roll_link">
    <inertial>
      <mass value="0.247936"/>
      <origin xyz="-0.006927 0.002039 -0.064837"/>
      <inertia ixx="0.004267" ixy="-0.000018322199" ixz="0.000017984455" iyy="0.000780923828" iyz="-0.00001392334" izz="0.00412"/>
    </inertial>
    <visual>
      <geometry>
        <mesh filename="package://tmc_hsrb_description/meshes/beetle/visual/arm_roll.dae"/>
      </geometry>
      <material name="body_main"/>
    </visual>
    <collision>
      <geometry>
        <mesh filename="package://tmc_hsrb_description/meshes/beetle/collision/arm_roll.stl"/>
      </geometry>
      <material name="body_main"/>
    </collision>
  </link>
  <joint name="hsr_beetle/wrist_flex_joint" type="revolute">
    <origin rpy="0.0 0.0 0.0" xyz="0.0 0.0 0.0"/>
    <axis xyz="0.0 -1.0 0.0"/>
    <limit effort="100.0" lower="-1.92" upper="1.22" velocity="1.5"/>
    <parent link="hsr_beetle/arm_roll_link"/>
    <child link="hsr_beetle/wrist_flex_link"/>
  </joint>
  <link name="hsr_beetle/wrist_flex_link">
    <inertial>
      <mass value="0.681225"/>
      <origin xyz="0.000131 -0.003929 0.00217"/>
      <inertia ixx="0.000074353558" ixy="0.000000494515" ixz="0.000000022937" iyy="0.000038432887" iyz="-0.00000255576" izz="0.000064680918"/>
    </inertial>
    <visual>
      <geometry>
        <mesh filename="package://tmc_hsrb_description/meshes/beetle/visual/wrist_flex.dae"/>
      </geometry>
      <material name="body_sub"/>
    </visual>
    <visual>
      <origin rpy="0.0 0.0 0.0" xyz="0.0 0.0 0.04"/>
      <geometry>
        <cylinder length="0.02" radius="0.017"/>
      </geometry>
      <material name="body_sub"/>
    </visual>
    <collision>
      <origin rpy="0.0 0.0 0.0" xyz="0.0 0.0 0.03"/>
      <geometry>
        <cylinder length="0.04" radius="0.017"/>
      </geometry>
      <material name="body_sub"/>
    </collision>
  </link>
  <joint name="hsr_beetle/wrist_roll_joint" type="revolute">
    <origin rpy="0.0 0.0 0.0" xyz="0.0 0.0 0.0"/>
    <axis xyz="0.0 0.0 1.0"/>
    <limit effort="100.0" lower="-3.84" upper="2.09" velocity="1.5"/>
    <parent link="hsr_beetle/wrist_flex_link"/>
    <child link="hsr_beetle/wrist_roll_link"/>
  </joint>
  <link name="hsr_beetle/wrist_roll_link">
    <inertial>
      <mass value="0.761692"/>
      <origin xyz="-0.001416 -0.001547 0.081689"/>
      <inertia ixx="0.000805633819" ixy="-0.000014431758" ixz="0.000028204659" iyy="0.000768077165" iyz="0.000022460226" izz="0.000453406611"/>
    </inertial>
    <visual>
      <geometry>
        <mesh filename="package://tmc_hsrb_description/meshes/beetle/visual/wrist_roll.dae"/>
      </geometry>
      <material name="body_main"/>
    </visual>
    <collision>
      <geometry>
        <mesh filename="package://tmc_hsrb_description/meshes/beetle/collision/wrist_roll.stl"/>
      </geometry>
      <material name="body_main"/>
    </collision>
  </link>
  <xacro:force_sensor parent="hsr_beetle/wrist_roll_link" prefix="hsr_beetle/wrist">
    <origin rpy="3.14159265359 0.0 0.0" xyz="0.0 0.0 0.0735"/>
  </xacro:force_sensor>
  <joint name="hsr_beetle/gripper_palm_joint" type="revolute">
    <origin rpy="0.0 0.0 3.14159265359" xyz="0.012 0.0 0.1405"/>
    <axis xyz="1.0 0.0 0.0"/>
    <limit effort="0.0" lower="0.0" upper="0.0" velocity="0.0"/>
    <parent link="hsr_beetle/wrist_roll_link"/>
    <child link="hsr_beetle/gripper_palm_link"/>
  </joint>
  <link name="hsr_beetle/gripper_palm_link">
    <visual>
      <geometry>
        <mesh filename="package://tmc_hsrb_description/meshes/beetle/visual/palm.dae"/>
      </geometry>
      <material name="body_sub"/>
    </visual>
    <collision>
      <geometry>
        <mesh filename="package://tmc_hsrb_description/meshes/beetle/collision/palm.stl"/>
      </geometry>
      <material name="body_sub"/>
    </collision>
    <inertial>
      <mass value="0.247936"/>
      <origin xyz="0 0 0"/>
      <inertia ixx="0.004267" ixy="-0.000018322199" ixz="0.000017984455" iyy="0.000780923828" iyz="-0.00001392334" izz="0.00412"/>
    </inertial>
  </link>
  <joint name="hsr_beetle/gripper_camera_joint" type="fixed">
    <origin rpy="3.14159265359 -1.5707963268 0" xyz="0.039 0.0 -0.0045"/>
    <parent link="hsr_beetle/gripper_palm_link"/>
    <child link="hsr_beetle/gripper_camera_link"/>
  </joint>
  <link name="hsr_beetle/gripper_camera_link">
    </link>
  <joint name="hsr_beetle/left_proximal_joint" type="revolute">
    <origin rpy="0.0 0.0 0.0" xyz="-0.01675                    -0.0245                    -0.0175"/>
    <axis xyz="1.0 0.0 0.0"/>
    <limit effort="100.0" lower="-0.1" upper="1.24" velocity="1.0"/>
    <parent link="hsr_beetle/gripper_palm_link"/>
    <child link="hsr_beetle/left_proximal_link"/>
  </joint>
  <link name="hsr_beetle/left_proximal_link">
    <inertial>
      <mass value="0.043589"/>
      <origin xyz="0.021418 0.00248 0.022688"/>
      <inertia ixx="0.000026033886" ixy="-0.000000144078" ixz="-0.00000198241" iyy="0.000028824811" iyz="-0.000001268421" izz="0.000005135919"/>
    </inertial>
    <visual>
      <geometry>
        <mesh filename="package://tmc_hsrb_description/meshes/beetle/visual/left_proximal.dae"/>
      </geometry>
      <material name="body_sub"/>
    </visual>
    <collision>
      <geometry>
        <mesh filename="package://tmc_hsrb_description/meshes/beetle/collision/left_proximal.stl"/>
      </geometry>
      <material name="body_sub"/>
    </collision>
  </link>
  <joint name="hsr_beetle/left_distal_joint" type="revolute">
    <origin rpy="0.0 0.0 0.0" xyz="0.0 0.0 0.07"/>
    <axis xyz="1.0 0.0 0.0"/>
    <limit effort="100.0" lower="-1.24" upper="0.1" velocity="1.0"/>
    <parent link="hsr_beetle/left_proximal_link"/>
    <child link="hsr_beetle/left_distal_link"/>
  </joint>
  <link name="hsr_beetle/left_distal_link">
    <inertial>
      <mass value="0.027731"/>
      <origin xyz="0.011116 0.005679 0.017532"/>
      <inertia ixx="0.000004451952" ixy="-0.000000617574" ixz="0.000000503765" iyy="0.000000503765" iyz="-0.000000435048" izz="0.000004456764"/>
    </inertial>
    <visual>
      <geometry>
        <mesh filename="package://tmc_hsrb_description/meshes/beetle/visual/left_distal.dae"/>
      </geometry>
      <material name="body_sub"/>
    </visual>
    <collision>
      <geometry>
        <mesh filename="package://tmc_hsrb_description/meshes/beetle/collision/left_distal.stl"/>
      </geometry>
      <material name="body_sub"/>
    </collision>
  </link>
  <joint name="hsr_beetle/left_finger_tip_joint" type="fixed">
    <origin rpy="-1.5707963268 0.0 0.0" xyz="0.01675 0.0193 0.0379"/>
    <parent link="hsr_beetle/left_distal_link"/>
    <child link="hsr_beetle/left_finger_tip_frame"/>
  </joint>
  <link name="hsr_beetle/left_finger_tip_frame">
    </link>
  <joint name="hsr_beetle/left_finger_vacuum_joint" type="fixed">
    <origin rpy="0.785398163398 0.0 0.0" xyz="0.00475 -0.011539 0.03322"/>
    <parent link="hsr_beetle/left_distal_link"/>
    <child link="hsr_beetle/left_finger_vacuum_frame"/>
  </joint>
  <link name="hsr_beetle/left_finger_vacuum_frame">
    <visual>
      <origin rpy="0.0 0.0 0.0" xyz="0.0 0.0 -0.01"/>
      <geometry>
        <box size="0.008 0.008 0.02"/>
      </geometry>
      <material name="body_sub"/>
    </visual>
  </link>
  <joint name="hsr_beetle/right_proximal_joint" type="revolute">
    <origin rpy="0.0 0.0 0.0" xyz="-0.01675                    0.0245                    -0.0175"/>
    <axis xyz="-1.0 0.0 0.0"/>
    <limit effort="100.0" lower="-0.1" upper="1.24" velocity="1.0"/>
    <parent link="hsr_beetle/gripper_palm_link"/>
    <child link="hsr_beetle/right_proximal_link"/>
  </joint>
  <link name="hsr_beetle/right_proximal_link">
    <inertial>
      <mass value="0.043956"/>
      <origin xyz="0.013203 0.002096 0.023311"/>
      <inertia ixx="0.00002623664" ixy="0.00000001631" ixz="0.000001281845" iyy="0.000028838232" iyz="-0.000001621709" izz="0.000004957151"/>
    </inertial>
    <visual>
      <geometry>
        <mesh filename="package://tmc_hsrb_description/meshes/beetle/visual/right_proximal.dae"/>
      </geometry>
      <material name="body_sub"/>
    </visual>
    <collision>
      <geometry>
        <mesh filename="package://tmc_hsrb_description/meshes/beetle/collision/right_proximal.stl"/>
      </geometry>
      <material name="body_sub"/>
    </collision>
  </link>
  <joint name="hsr_beetle/right_distal_joint" type="revolute">
    <origin rpy="0.0 0.0 0.0" xyz="0.0 0.0 0.07"/>
    <axis xyz="-1.0 0.0 0.0"/>
    <limit effort="100.0" lower="-1.24" upper="0.1" velocity="1.0"/>
    <parent link="hsr_beetle/right_proximal_link"/>
    <child link="hsr_beetle/right_distal_link"/>
  </joint>
  <link name="hsr_beetle/right_distal_link">
    <inertial>
      <mass value="0.020927"/>
      <origin xyz="0.014256 -0.008321 0.015591"/>
      <inertia ixx="0.00000307518" ixy="0.000004176168" ixz="0.000002877537" iyy="-0.000000049953" iyz="0.000000010237" izz="0.000000866222"/>
    </inertial>
    <visual>
      <geometry>
        <mesh filename="package://tmc_hsrb_description/meshes/beetle/visual/right_distal.dae"/>
      </geometry>
      <material name="body_sub"/>
    </visual>
    <collision>
      <geometry>
        <mesh filename="package://tmc_hsrb_description/meshes/beetle/collision/right_distal.stl"/>
      </geometry>
      <material name="body_sub"/>
    </collision>
  </link>
  <joint name="hsr_beetle/right_finger_tip_joint" type="fixed">
    <origin rpy="1.5707963268 0.0 0.0" xyz="0.01675 -0.0193 0.0379"/>
    <parent link="hsr_beetle/right_distal_link"/>
    <child link="hsr_beetle/right_finger_tip_frame"/>
  </joint>
  <link name="hsr_beetle/right_finger_tip_frame">
    </link>
</robot>

